Workbook

Sheet titanic
A1: survived | B1: pclass | C1: sex | D1: age | E1: sibsp | F1: parch | G1: fare | H1: embarked | I1: class | J1: who | K1: adult_male | L1: deck | M1: embark_town | N1: alive | O1: alone
A2: 0 | B2: 3 | C2: male | D2: 22 | E2: 1 | F2: 0 | G2: 7.25 | H2: S | I2: Third | J2: man | K2: TRUE | M2: Southampton | N2: no | O2: FALSE
A3: 1 | B3: 1 | C3: female | D3: 38 | E3: 1 | F3: 0 | G3: 71.2833 | H3: C | I3: First | J3: woman | K3: FALSE | L3: C | M3: Cherbourg | N3: yes | O3: FALSE
A4: 1 | B4: 3 | C4: female | D4: 26 | E4: 0 | F4: 0 | G4: 7.925 | H4: S | I4: Third | J4: woman | K4: FALSE | M4: Southampton | N4: yes | O4: TRUE
A5: 1 | B5: 1 | C5: female | D5: 35 | E5: 1 | F5: 0 | G5: 53.1 | H5: S | I5: First | J5: woman | K5: FALSE | L5: C | M5: Southampton | N5: yes | O5: FALSE
A6: 0 | B6: 3 | C6: male | D6: 35 | E6: 0 | F6: 0 | G6: 8.05 | H6: S | I6: Third | J6: man | K6: TRUE | M6: Southampton | N6: no | O6: TRUE
A7: 0 | B7: 3 | C7: male | E7: 0 | F7: 0 | G7: 8.4583 | H7: Q | I7: Third | J7: man | K7: TRUE | M7: Queenstown | N7: no | O7: TRUE
A8: 0 | B8: 1 | C8: male | D8: 54 | E8: 0 | F8: 0 | G8: 51.8625 | H8: S | I8: First | J8: man | K8: TRUE | L8: E | M8: Southampton | N8: no | O8: TRUE
A9: 0 | B9: 3 | C9: male | D9: 2 | E9: 3 | F9: 1 | G9: 21.075 | H9: S | I9: Third | J9: child | K9: FALSE | M9: Southampton | N9: no | O9: FALSE
A10: 1 | B10: 3 | C10: female | D10: 27 | E10: 0 | F10: 2 | G10: 11.1333 | H10: S | I10: Third | J10: woman | K10: FALSE | M10: Southampton | N10: yes | O10: FALSE
A11: 1 | B11: 2 | C11: female | D11: 14 | E11: 1 | F11: 0 | G11: 30.0708 | H11: C | I11: Second | J11: child | K11: FALSE | M11: Cherbourg | N11: yes | O11: FALSE
A12: 1 | B12: 3 | C12: female | D12: 4 | E12: 1 | F12: 1 | G12: 16.7 | H12: S | I12: Third | J12: child | K12: FALSE | L12: G | M12: Southampton | N12: yes | O12: FALSE
A13: 1 | B13: 1 | C13: female | D13: 58 | E13: 0 | F13: 0 | G13: 26.55 | H13: S | I13: First | J13: woman | K13: FALSE | L13: C | M13: Southampton | N13: yes | O13: TRUE
A14: 0 | B14: 3 | C14: male | D14: 20 | E14: 0 | F14: 0 | G14: 8.05 | H14: S | I14: Third | J14: man | K14: TRUE | M14: Southampton | N14: no | O14: TRUE
A15: 0 | B15: 3 | C15: male | D15: 39 | E15: 1 | F15: 5 | G15: 31.275 | H15: S | I15: Third | J15: man | K15: TRUE | M15: Southampton | N15: no | O15: FALSE
A16: 0 | B16: 3 | C16: female | D16: 14 | E16: 0 | F16: 0 | G16: 7.8542 | H16: S | I16: Third | J16: child | K16: FALSE | M16: Southampton | N16: no | O16: TRUE
A17: 1 | B17: 2 | C17: female | D17: 55 | E17: 0 | F17: 0 | G17: 16 | H17: S | I17: Second | J17: woman | K17: FALSE | M17: Southampton | N17: yes | O17: TRUE
A18: 0 | B18: 3 | C18: male | D18: 2 | E18: 4 | F18: 1 | G18: 29.125 | H18: Q | I18: Third | J18: child | K18: FALSE | M18: Queenstown | N18: no | O18: FALSE
A19: 1 | B19: 2 | C19: male | E19: 0 | F19: 0 | G19: 13 | H19: S | I19: Second | J19: man | K19: TRUE | M19: Southampton | N19: yes | O19: TRUE
A20: 0 | B20: 3 | C20: female | D20: 31 | E20: 1 | F20: 0 | G20: 18 | H20: S | I20: Third | J20: woman | K20: FALSE | M20: Southampton | N20: no | O20: FALSE
A21: 1 | B21: 3 | C21: female | E21: 0 | F21: 0 | G21: 7.225 | H21: C | I21: Third | J21: woman | K21: FALSE | M21: Cherbourg | N21: yes | O21: TRUE
A22: 0 | B22: 2 | C22: male | D22: 35 | E22: 0 | F22: 0 | G22: 26 | H22: S | I22: Second | J22: man | K22: TRUE | M22: Southampton | N22: no | O22: TRUE
A23: 1 | B23: 2 | C23: male | D23: 34 | E23: 0 | F23: 0 | G23: 13 | H23: S | I23: Second | J23: man | K23: TRUE | L23: D | M23: Southampton | N23: yes | O23: TRUE
A24: 1 | B24: 3 | C24: female | D24: 15 | E24: 0 | F24: 0 | G24: 8.0292 | H24: Q | I24: Third | J24: child | K24: FALSE | M24: Queenstown | N24: yes | O24: TRUE
A25: 1 | B25: 1 | C25: male | D25: 28 | E25: 0 | F25: 0 | G25: 35.5 | H25: S | I25: First | J25: man | K25: TRUE | L25: A | M25: Southampton | N25: yes | O25: TRUE
A26: 0 | B26: 3 | C26: female | D26: 8 | E26: 3 | F26: 1 | G26: 21.075 | H26: S | I26: Third | J26: child | K26: FALSE | M26: Southampton | N26: no | O26: FALSE
A27: 1 | B27: 3 | C27: female | D27: 38 | E27: 1 | F27: 5 | G27: 31.3875 | H27: S | I27: Third | J27: woman | K27: FALSE | M27: Southampton | N27: yes | O27: FALSE
A28: 0 | B28: 3 | C28: male | E28: 0 | F28: 0 | G28: 7.225 | H28: C | I28: Third | J28: man | K28: TRUE | M28: Cherbourg | N28: no | O28: TRUE
A29: 0 | B29: 1 | C29: male | D29: 19 | E29: 3 | F29: 2 | G29: 263 | H29: S | I29: First | J29: man | K29: TRUE | L29: C | M29: Southampton | N29: no | O29: FALSE
A30: 1 | B30: 3 | C30: female | E30: 0 | F30: 0 | G30: 7.8792 | H30: Q | I30: Third | J30: woman | K30: FALSE | M30: Queenstown | N30: yes | O30: TRUE
A31: 0 | B31: 3 | C31: male | E31: 0 | F31: 0 | G31: 7.8958 | H31: S | I31: Third | J31: man | K31: TRUE | M31: Southampton | N31: no | O31: TRUE
A32: 0 | B32: 1 | C32: male | D32: 40 | E32: 0 | F32: 0 | G32: 27.7208 | H32: C | I32: First | J32: man | K32: TRUE | M32: Cherbourg | N32: no | O32: TRUE
A33: 1 | B33: 1 | C33: female | E33: 1 | F33: 0 | G33: 146.5208 | H33: C | I33: First | J33: woman | K33: FALSE | L33: B | M33: Cherbourg | N33: yes | O33: FALSE
A34: 1 | B34: 3 | C34: female | E34: 0 | F34: 0 | G34: 7.75 | H34: Q | I34: Third | J34: woman | K34: FALSE | M34: Queenstown | N34: yes | O34: TRUE
A35: 0 | B35: 2 | C35: male | D35: 66 | E35: 0 | F35: 0 | G35: 10.5 | H35: S | I35: Second | J35: man | K35: TRUE | M35: Southampton | N35: no | O35: TRUE
A36: 0 | B36: 1 | C36: male | D36: 28 | E36: 1 | F36: 0 | G36: 82.1708 | H36: C | I36: First | J36: man | K36: TRUE | M36: Cherbourg | N36: no | O36: FALSE
A37: 0 | B37: 1 | C37: male | D37: 42 | E37: 1 | F37: 0 | G37: 52 | H37: S | I37: First | J37: man | K37: TRUE | M37: Southampton | N37: no | O37: FALSE
A38: 1 | B38: 3 | C38: male | E38: 0 | F38: 0 | G38: 7.2292 | H38: C | I38: Third | J38: man | K38: TRUE | M38: Cherbourg | N38: yes | O38: TRUE
A39: 0 | B39: 3 | C39: male | D39: 21 | E39: 0 | F39: 0 | G39: 8.05 | H39: S | I39: Third | J39: man | K39: TRUE | M39: Southampton | N39: no | O39: TRUE
A40: 0 | B40: 3 | C40: female | D40: 18 | E40: 2 | F40: 0 | G40: 18 | H40: S | I40: Third | J40: woman | K40: FALSE | M40: Southampton | N40: no | O40: FALSE
...

Sheet Missing Value Summary
A1: Column | B1: Missing Values | C1: Total Values | D1: Missing%
A2: survived | B2: =COUNTBLANK(titanic!A2:A892) -> 0 | C2: =ROWS(titanic!A2:A892) -> 891 | D2: =B2/C2 -> 0
A3: pclass | B3: =COUNTBLANK(titanic!B2:B892) -> 0 | C3: =ROWS(titanic!A3:A893) -> 891 | D3: =B3/C3 -> 0
A4: sex | B4: =COUNTBLANK(titanic!C2:C892) -> 0 | C4: =ROWS(titanic!A4:A894) -> 891 | D4: =B4/C4 -> 0
A5: age | B5: =COUNTBLANK(titanic!D2:D892) -> 177 | C5: =ROWS(titanic!A5:A895) -> 891 | D5: =B5/C5 -> 0.1986532
A6: sibsp | B6: =COUNTBLANK(titanic!E2:E892) -> 0 | C6: =ROWS(titanic!A6:A896) -> 891 | D6: =B6/C6 -> 0
A7: parch | B7: =COUNTBLANK(titanic!F2:F892) -> 0 | C7: =ROWS(titanic!A7:A897) -> 891 | D7: =B7/C7 -> 0
A8: fare | B8: =COUNTBLANK(titanic!G2:G892) -> 0 | C8: =ROWS(titanic!A8:A898) -> 891 | D8: =B8/C8 -> 0
A9: embarked | B9: =COUNTBLANK(titanic!H2:H892) -> 2 | C9: =ROWS(titanic!A9:A899) -> 891 | D9: =B9/C9 -> 0.0022446689
A10: class | B10: =COUNTBLANK(titanic!I2:I892) -> 0 | C10: =ROWS(titanic!A10:A900) -> 891 | D10: =B10/C10 -> 0
A11: who | B11: =COUNTBLANK(titanic!J2:J892) -> 0 | C11: =ROWS(titanic!A11:A901) -> 891 | D11: =B11/C11 -> 0
A12: adult_male | B12: =COUNTBLANK(titanic!K2:K892) -> 0 | C12: =ROWS(titanic!A12:A902) -> 891 | D12: =B12/C12 -> 0
A13: deck | B13: =COUNTBLANK(titanic!L2:L892) -> 688 | C13: =ROWS(titanic!A13:A903) -> 891 | D13: =B13/C13 -> 0.77216611
A14: embark_town | B14: =COUNTBLANK(titanic!M2:M892) -> 2 | C14: =ROWS(titanic!A14:A904) -> 891 | D14: =B14/C14 -> 0.0022446689
A15: alive | B15: =COUNTBLANK(titanic!N2:N892) -> 0 | C15: =ROWS(titanic!A15:A905) -> 891 | D15: =B15/C15 -> 0
A16: alone | B16: =COUNTBLANK(titanic!O2:O892) -> 0 | C16: =ROWS(titanic!A16:A906) -> 891 | D16: =B16/C16 -> 0
A18: A19: | J18: A24:
A19: The Titanic dataset contains 891 passenger records and 15 columns. | J19: Missing values should be handled appropriately rather than removing records without justification.
A21: A20:
A22: The deck column has the highest number of missing values, with 688 missing entries (77.22%).
A24: A21:
A25: The age column has 177 missing values (19.87%).
A27: A22:
A28: The embarked and embark_town columns each have 2 missing values (0.22%).
A30: A23:
A31: The remaining columns do not contain missing values.
